Workbook

Sheet F series
A1: Corp. | B1: 기준가 | C1: 수량 | D1: 단가 | E1: 대비 | F1: Low | G1: High | H1: L date | I1: H (cf. L) | J1: H/L | K1: F2 | L1: F3 | M1: F4 | N1: F5 | O1: F series | P1: buy2(cf. H) | Q1: buy3(cf. 2) | R1: buy4(cf. 3) | S1: sell(cf. buy) | T1: sell date | U1: sell price | V1: rbn rate | X1: 50
C2: =IFERROR($X$1*10000/D2,"") | E2: =IFERROR(D2/B2-1,"") | J2: =IFERROR(G2/F2-1,"") | K2: =IFERROR(ROUND($F2+($G2-$F2)*0.632,0),"") -> 0 | L2: =IFERROR(ROUND($F2+($G2-$F2)*0.5,0),"") -> 0 | M2: =IFERROR(ROUND($F2+($G2-$F2)*0.368,0),"") -> 0 | N2: =IFERROR(ROUND($F2+($G2-$F2)*0.214,0),"") -> 0 | V2: {=IFERROR(_xlfn.IFS(O2="F2",U2/K2,O2="F23",U2/L2,O2="F234",U2/M2,O2="F3",U2/L2,O2="F34",U2/M2,O2="F234손절",U2/K2,O2="F2345손절",U2/K2,O2="F34손절",U2/L2,O2="F345손절",U2/L2)-1,"")}
A3: 와이즈버즈 | B3: 1674 | C3: =IFERROR($X$1*10000/D3,"") | E3: =IFERROR(D3/B3-1,"") -> -1 | J3: =IFERROR(G3/F3-1,"") | K3: =COUNTIFS('F series'!T12:T40,#REF!, 'F series'!O12:O40,#REF!) -> 0 | L3: =IFERROR(ROUND($F3+($G3-$F3)*0.5,0),"") -> 0 | M3: =IFERROR(ROUND($F3+($G3-$F3)*0.368,0),"") -> 0 | N3: =IFERROR(ROUND($F3+($G3-$F3)*0.214,0),"") -> 0 | V3: {=IFERROR(_xlfn.IFS(O3="F2",U3/K3,O3="F23",U3/L3,O3="F234",U3/M3,O3="F3",U3/L3,O3="F34",U3/M3,O3="F234손절",U3/K3,O3="F2345손절",U3/K3,O3="F34손절",U3/L3,O3="F345손절",U3/L3)-1,"")}
A4: 모비데이즈 | B4: 1212 | C4: =IFERROR($X$1*10000/D4,"") | E4: =IFERROR(D4/B4-1,"") -> -1 | J4: =IFERROR(G4/F4-1,"") | K4: =IFERROR(ROUND($F4+($G4-$F4)*0.632,0),"") -> 0 | L4: =IFERROR(ROUND($F4+($G4-$F4)*0.5,0),"") -> 0 | M4: =IFERROR(ROUND($F4+($G4-$F4)*0.368,0),"") -> 0 | N4: =IFERROR(ROUND($F4+($G4-$F4)*0.214,0),"") -> 0 | V4: {=IFERROR(_xlfn.IFS(O4="F2",U4/K4,O4="F23",U4/L4,O4="F234",U4/M4,O4="F3",U4/L4,O4="F34",U4/M4,O4="F234손절",U4/K4,O4="F2345손절",U4/K4,O4="F34손절",U4/L4,O4="F345손절",U4/L4)-1,"")}
A5: 플레이디 | B5: 6650 | C5: =IFERROR($X$1*10000/D5,"") | E5: =IFERROR(D5/B5-1,"") -> -1 | J5: =IFERROR(G5/F5-1,"") | K5: =IFERROR(ROUND($F5+($G5-$F5)*0.632,0),"") -> 0 | L5: =IFERROR(ROUND($F5+($G5-$F5)*0.5,0),"") -> 0 | M5: =IFERROR(ROUND($F5+($G5-$F5)*0.368,0),"") -> 0 | N5: =IFERROR(ROUND($F5+($G5-$F5)*0.214,0),"") -> 0 | V5: {=IFERROR(_xlfn.IFS(O5="F2",U5/K5,O5="F23",U5/L5,O5="F234",U5/M5,O5="F3",U5/L5,O5="F34",U5/M5,O5="F234손절",U5/K5,O5="F2345손절",U5/K5,O5="F34손절",U5/L5,O5="F345손절",U5/L5)-1,"")}
C6: =IFERROR($X$1*10000/D6,"") | E6: =IFERROR(D6/B6-1,"") | J6: =IFERROR(G6/F6-1,"") | K6: =IFERROR(ROUND($F6+($G6-$F6)*0.632,0),"") -> 0 | L6: =IFERROR(ROUND($F6+($G6-$F6)*0.5,0),"") -> 0 | M6: =IFERROR(ROUND($F6+($G6-$F6)*0.368,0),"") -> 0 | N6: =IFERROR(ROUND($F6+($G6-$F6)*0.214,0),"") -> 0 | V6: {=IFERROR(_xlfn.IFS(O6="F2",U6/K6,O6="F23",U6/L6,O6="F234",U6/M6,O6="F3",U6/L6,O6="F34",U6/M6,O6="F234손절",U6/K6,O6="F2345손절",U6/K6,O6="F34손절",U6/L6,O6="F345손절",U6/L6)-1,"")}
A7: 가온칩스 | B7: 37500 | C7: =IFERROR($X$1*10000/D7,"") -> 14.184397 | D7: 35250 | E7: =IFERROR(D7/B7-1,"") -> -0.06 | F7: 30700 | G7: 39850 | H7: 45107 | I7: +3 | J7: =IFERROR(G7/F7-1,"") -> 0.2980456 | K7: =IFERROR(ROUND($F7+($G7-$F7)*0.632,0),"") -> 36483 | L7: =IFERROR(ROUND($F7+($G7-$F7)*0.5,0),"") -> 35275 | M7: =IFERROR(ROUND($F7+($G7-$F7)*0.368,0),"") -> 34067 | N7: =IFERROR(ROUND($F7+($G7-$F7)*0.214,0),"") -> 32658 | P7: +2 | V7: {=IFERROR(_xlfn.IFS(O7="F2",U7/K7,O7="F23",U7/L7,O7="F234",U7/M7,O7="F3",U7/L7,O7="F34",U7/M7,O7="F234손절",U7/K7,O7="F2345손절",U7/K7,O7="F34손절",U7/L7,O7="F345손절",U7/L7)-1,"")}
A8: 마이크로투나노 | B8: 23100 | C8: =IFERROR($X$1*10000/D8,"") -> 23.094688 | D8: 21650 | E8: =IFERROR(D8/B8-1,"") -> -0.062770563 | F8: 18100 | G8: 25250 | H8: 45107 | I8: +3 | J8: =IFERROR(G8/F8-1,"") -> 0.39502762 | K8: =IFERROR(ROUND($F8+($G8-$F8)*0.632,0),"") -> 22619 | L8: =IFERROR(ROUND($F8+($G8-$F8)*0.5,0),"") -> 21675 | M8: =IFERROR(ROUND($F8+($G8-$F8)*0.368,0),"") -> 20731 | N8: =IFERROR(ROUND($F8+($G8-$F8)*0.214,0),"") -> 19630 | P8: +1 | V8: {=IFERROR(_xlfn.IFS(O8="F2",U8/K8,O8="F23",U8/L8,O8="F234",U8/M8,O8="F3",U8/L8,O8="F34",U8/M8,O8="F234손절",U8/K8,O8="F2345손절",U8/K8,O8="F34손절",U8/L8,O8="F345손절",U8/L8)-1,"")}
A9: 덕산하이메탈 | B9: 9240 | C9: =IFERROR($X$1*10000/D9,"") -> 59.594756 | D9: 8390 | E9: =IFERROR(D9/B9-1,"") -> -0.091991342 | F9: 6890 | G9: 9890 | H9: 45107 | I9: +5 | J9: =IFERROR(G9/F9-1,"") -> 0.43541364 | K9: =IFERROR(ROUND($F9+($G9-$F9)*0.632,0),"") -> 8786 | L9: =IFERROR(ROUND($F9+($G9-$F9)*0.5,0),"") -> 8390 | M9: =IFERROR(ROUND($F9+($G9-$F9)*0.368,0),"") -> 7994 | N9: =IFERROR(ROUND($F9+($G9-$F9)*0.214,0),"") -> 7532 | V9: {=IFERROR(_xlfn.IFS(O9="F2",U9/K9,O9="F23",U9/L9,O9="F234",U9/M9,O9="F3",U9/L9,O9="F34",U9/M9,O9="F234손절",U9/K9,O9="F2345손절",U9/K9,O9="F34손절",U9/L9,O9="F345손절",U9/L9)-1,"")}
A10: 칩스앤미디어 | B10: 36400 | C10: =IFERROR($X$1*10000/D10,"") -> 14.245014 | D10: 35100 | E10: =IFERROR(D10/B10-1,"") -> -0.035714286 | F10: 30600 | G10: 42950 | H10: 45107 | I10: +3 | J10: =IFERROR(G10/F10-1,"") -> 0.40359477 | K10: =IFERROR(ROUND($F10+($G10-$F10)*0.632,0),"") -> 38405 | L10: =IFERROR(ROUND($F10+($G10-$F10)*0.5,0),"") -> 36775 | M10: =IFERROR(ROUND($F10+($G10-$F10)*0.368,0),"") -> 35145 | N10: =IFERROR(ROUND($F10+($G10-$F10)*0.214,0),"") -> 33243 | P10: +1 | Q10: +1 | V10: {=IFERROR(_xlfn.IFS(O10="F2",U10/K10,O10="F23",U10/L10,O10="F234",U10/M10,O10="F3",U10/L10,O10="F34",U10/M10,O10="F234손절",U10/K10,O10="F2345손절",U10/K10,O10="F34손절",U10/L10,O10="F345손절",U10/L10)-1,"")}
A11: 프로텍 | B11: 56000 | C11: =IFERROR($X$1*10000/D11,"") | E11: =IFERROR(D11/B11-1,"") -> -1 | J11: =IFERROR(G11/F11-1,"") | K11: =IFERROR(ROUND($F11+($G11-$F11)*0.632,0),"") -> 0 | L11: =IFERROR(ROUND($F11+($G11-$F11)*0.5,0),"") -> 0 | M11: =IFERROR(ROUND($F11+($G11-$F11)*0.368,0),"") -> 0 | N11: =IFERROR(ROUND($F11+($G11-$F11)*0.214,0),"") -> 0 | V11: {=IFERROR(_xlfn.IFS(O11="F2",U11/K11,O11="F23",U11/L11,O11="F234",U11/M11,O11="F3",U11/L11,O11="F34",U11/M11,O11="F234손절",U11/K11,O11="F2345손절",U11/K11,O11="F34손절",U11/L11,O11="F345손절",U11/L11)-1,"")}
A12: 펨트론 | B12: 16200 | C12: =IFERROR($X$1*10000/D12,"") -> 32.071841 | D12: 15590 | E12: =IFERROR(D12/B12-1,"") -> -0.037654321 | F12: 13380 | G12: 19410 | H12: 45106 | I12: +3 | J12: =IFERROR(G12/F12-1,"") -> 0.45067265 | K12: =IFERROR(ROUND($F12+($G12-$F12)*0.632,0),"") -> 17191 | L12: =IFERROR(ROUND($F12+($G12-$F12)*0.5,0),"") -> 16395 | M12: =IFERROR(ROUND($F12+($G12-$F12)*0.368,0),"") -> 15599 | N12: =IFERROR(ROUND($F12+($G12-$F12)*0.214,0),"") -> 14670 | P12: +2 | Q12: +1 | V12: {=IFERROR(_xlfn.IFS(O12="F2",U12/K12,O12="F23",U12/L12,O12="F234",U12/M12,O12="F3",U12/L12,O12="F34",U12/M12,O12="F234손절",U12/K12,O12="F2345손절",U12/K12,O12="F34손절",U12/L12,O12="F345손절",U12/L12)-1,"")}
A13: 기가비스 | B13: 92200 | C13: =IFERROR($X$1*10000/D13,"") | E13: =IFERROR(D13/B13-1,"") -> -1 | J13: =IFERROR(G13/F13-1,"") | K13: =IFERROR(ROUND($F13+($G13-$F13)*0.632,0),"") -> 0 | L13: =IFERROR(ROUND($F13+($G13-$F13)*0.5,0),"") -> 0 | M13: =IFERROR(ROUND($F13+($G13-$F13)*0.368,0),"") -> 0 | N13: =IFERROR(ROUND($F13+($G13-$F13)*0.214,0),"") -> 0 | V13: {=IFERROR(_xlfn.IFS(O13="F2",U13/K13,O13="F23",U13/L13,O13="F234",U13/M13,O13="F3",U13/L13,O13="F34",U13/M13,O13="F234손절",U13/K13,O13="F2345손절",U13/K13,O13="F34손절",U13/L13,O13="F345손절",U13/L13)-1,"")}
A14: 티에프이 | B14: 22200 | C14: =IFERROR($X$1*10000/D14,"") -> 25.974026 | D14: 19250 | E14: =IFERROR(D14/B14-1,"") -> -0.13288288 | F14: 15580 | G14: 22950 | H14: 45111 | I14: +3 | J14: =IFERROR(G14/F14-1,"") -> 0.47304236 | K14: =IFERROR(ROUND($F14+($G14-$F14)*0.632,0),"") -> 20238 | L14: =IFERROR(ROUND($F14+($G14-$F14)*0.5,0),"") -> 19265 | M14: =IFERROR(ROUND($F14+($G14-$F14)*0.368,0),"") -> 18292 | N14: =IFERROR(ROUND($F14+($G14-$F14)*0.214,0),"") -> 17157 | V14: {=IFERROR(_xlfn.IFS(O14="F2",U14/K14,O14="F23",U14/L14,O14="F234",U14/M14,O14="F3",U14/L14,O14="F34",U14/M14,O14="F234손절",U14/K14,O14="F2345손절",U14/K14,O14="F34손절",U14/L14,O14="F345손절",U14/L14)-1,"")}
A15: 이수페타시스 | B15: 29400 | C15: =IFERROR($X$1*10000/D15,"") | E15: =IFERROR(D15/B15-1,"") -> -1 | J15: =IFERROR(G15/F15-1,"") | K15: =IFERROR(ROUND($F15+($G15-$F15)*0.632,0),"") -> 0 | L15: =IFERROR(ROUND($F15+($G15-$F15)*0.5,0),"") -> 0 | M15: =IFERROR(ROUND($F15+($G15-$F15)*0.368,0),"") -> 0 | N15: =IFERROR(ROUND($F15+($G15-$F15)*0.214,0),"") -> 0 | V15: {=IFERROR(_xlfn.IFS(O15="F2",U15/K15,O15="F23",U15/L15,O15="F234",U15/M15,O15="F3",U15/L15,O15="F34",U15/M15,O15="F234손절",U15/K15,O15="F2345손절",U15/K15,O15="F34손절",U15/L15,O15="F345손절",U15/L15)-1,"")}
C16: =IFERROR($X$1*10000/D16,"") | E16: =IFERROR(D16/B16-1,"") | J16: =IFERROR(G16/F16-1,"") | K16: =IFERROR(ROUND($F16+($G16-$F16)*0.632,0),"") -> 0 | L16: =IFERROR(ROUND($F16+($G16-$F16)*0.5,0),"") -> 0 | M16: =IFERROR(ROUND($F16+($G16-$F16)*0.368,0),"") -> 0 | N16: =IFERROR(ROUND($F16+($G16-$F16)*0.214,0),"") -> 0 | V16: {=IFERROR(_xlfn.IFS(O16="F2",U16/K16,O16="F23",U16/L16,O16="F234",U16/M16,O16="F3",U16/L16,O16="F34",U16/M16,O16="F234손절",U16/K16,O16="F2345손절",U16/K16,O16="F34손절",U16/L16,O16="F345손절",U16/L16)-1,"")}
A17: 루닛 | B17: 183100 | C17: =IFERROR($X$1*10000/D17,"") | E17: =IFERROR(D17/B17-1,"") -> -1 | J17: =IFERROR(G17/F17-1,"") | K17: =IFERROR(ROUND($F17+($G17-$F17)*0.632,0),"") -> 0 | L17: =IFERROR(ROUND($F17+($G17-$F17)*0.5,0),"") -> 0 | M17: =IFERROR(ROUND($F17+($G17-$F17)*0.368,0),"") -> 0 | N17: =IFERROR(ROUND($F17+($G17-$F17)*0.214,0),"") -> 0 | V17: {=IFERROR(_xlfn.IFS(O17="F2",U17/K17,O17="F23",U17/L17,O17="F234",U17/M17,O17="F3",U17/L17,O17="F34",U17/M17,O17="F234손절",U17/K17,O17="F2345손절",U17/K17,O17="F34손절",U17/L17,O17="F345손절",U17/L17)-1,"")}
A18: 뷰노 | B18: 31700 | C18: =IFERROR($X$1*10000/D18,"") | E18: =IFERROR(D18/B18-1,"") -> -1 | J18: =IFERROR(G18/F18-1,"") | K18: =IFERROR(ROUND($F18+($G18-$F18)*0.632,0),"") -> 0 | L18: =IFERROR(ROUND($F18+($G18-$F18)*0.5,0),"") -> 0 | M18: =IFERROR(ROUND($F18+($G18-$F18)*0.368,0),"") -> 0 | N18: =IFERROR(ROUND($F18+($G18-$F18)*0.214,0),"") -> 0 | V18: {=IFERROR(_xlfn.IFS(O18="F2",U18/K18,O18="F23",U18/L18,O18="F234",U18/M18,O18="F3",U18/L18,O18="F34",U18/M18,O18="F234손절",U18/K18,O18="F2345손절",U18/K18,O18="F34손절",U18/L18,O18="F345손절",U18/L18)-1,"")}
A19: 지니너스 | B19: 3335 | C19: =IFERROR($X$1*10000/D19,"") | E19: =IFERROR(D19/B19-1,"") -> -1 | J19: =IFERROR(G19/F19-1,"") | K19: =COUNTIFS('F series'!T28:T56,#REF!, 'F series'!O28:O56,#REF!) -> 0 | L19: =IFERROR(ROUND($F19+($G19-$F19)*0.5,0),"") -> 0 | M19: =IFERROR(ROUND($F19+($G19-$F19)*0.368,0),"") -> 0 | N19: =IFERROR(ROUND($F19+($G19-$F19)*0.214,0),"") -> 0 | V19: {=IFERROR(_xlfn.IFS(O19="F2",U19/K19,O19="F23",U19/L19,O19="F234",U19/M19,O19="F3",U19/L19,O19="F34",U19/M19,O19="F234손절",U19/K19,O19="F2345손절",U19/K19,O19="F34손절",U19/L19,O19="F345손절",U19/L19)-1,"")}
A20: 인성정보 | B20: 3500 | C20: =IFERROR($X$1*10000/D20,"") | E20: =IFERROR(D20/B20-1,"") -> -1 | J20: =IFERROR(G20/F20-1,"") | K20: =IFERROR(ROUND($F20+($G20-$F20)*0.632,0),"") -> 0 | L20: =IFERROR(ROUND($F20+($G20-$F20)*0.5,0),"") -> 0 | M20: =IFERROR(ROUND($F20+($G20-$F20)*0.368,0),"") -> 0 | N20: =IFERROR(ROUND($F20+($G20-$F20)*0.214,0),"") -> 0 | V20: {=IFERROR(_xlfn.IFS(O20="F2",U20/K20,O20="F23",U20/L20,O20="F234",U20/M20,O20="F3",U20/L20,O20="F34",U20/M20,O20="F234손절",U20/K20,O20="F2345손절",U20/K20,O20="F34손절",U20/L20,O20="F345손절",U20/L20)-1,"")}
C21: =IFERROR($X$1*10000/D21,"") | E21: =IFERROR(D21/B21-1,"") | J21: =IFERROR(G21/F21-1,"") | K21: =IFERROR(ROUND($F21+($G21-$F21)*0.632,0),"") -> 0 | L21: =IFERROR(ROUND($F21+($G21-$F21)*0.5,0),"") -> 0 | M21: =IFERROR(ROUND($F21+($G21-$F21)*0.368,0),"") -> 0 | N21: =IFERROR(ROUND($F21+($G21-$F21)*0.214,0),"") -> 0 | V21: {=IFERROR(_xlfn.IFS(O21="F2",U21/K21,O21="F23",U21/L21,O21="F234",U21/M21,O21="F3",U21/L21,O21="F34",U21/M21,O21="F234손절",U21/K21,O21="F2345손절",U21/K21,O21="F34손절",U21/L21,O21="F345손절",U21/L21)-1,"")}
A22: 큐렉소 | B22: 18800 | C22: =IFERROR($X$1*10000/D22,"") | E22: =IFERROR(D22/B22-1,"") -> -1 | J22: =IFERROR(G22/F22-1,"") | K22: =IFERROR(ROUND($F22+($G22-$F22)*0.632,0),"") -> 0 | L22: =IFERROR(ROUND($F22+($G22-$F22)*0.5,0),"") -> 0 | M22: =IFERROR(ROUND($F22+($G22-$F22)*0.368,0),"") -> 0 | N22: =IFERROR(ROUND($F22+($G22-$F22)*0.214,0),"") -> 0 | V22: {=IFERROR(_xlfn.IFS(O22="F2",U22/K22,O22="F23",U22/L22,O22="F234",U22/M22,O22="F3",U22/L22,O22="F34",U22/M22,O22="F234손절",U22/K22,O22="F2345손절",U22/K22,O22="F34손절",U22/L22,O22="F345손절",U22/L22)-1,"")}
A23: 미래컴퍼니 | B23: 35700 | C23: =IFERROR($X$1*10000/D23,"") | E23: =IFERROR(D23/B23-1,"") -> -1 | J23: =IFERROR(G23/F23-1,"") | K23: =IFERROR(ROUND($F23+($G23-$F23)*0.632,0),"") -> 0 | L23: =IFERROR(ROUND($F23+($G23-$F23)*0.5,0),"") -> 0 | M23: =IFERROR(ROUND($F23+($G23-$F23)*0.368,0),"") -> 0 | N23: =IFERROR(ROUND($F23+($G23-$F23)*0.214,0),"") -> 0 | V23: {=IFERROR(_xlfn.IFS(O23="F2",U23/K23,O23="F23",U23/L23,O23="F234",U23/M23,O23="F3",U23/L23,O23="F34",U23/M23,O23="F234손절",U23/K23,O23="F2345손절",U23/K23,O23="F34손절",U23/L23,O23="F345손절",U23/L23)-1,"")}
C24: =IFERROR($X$1*10000/D24,"") | E24: =IFERROR(D24/B24-1,"") | J24: =IFERROR(G24/F24-1,"") | K24: =IFERROR(ROUND($F24+($G24-$F24)*0.632,0),"") -> 0 | L24: =IFERROR(ROUND($F24+($G24-$F24)*0.5,0),"") -> 0 | M24: =IFERROR(ROUND($F24+($G24-$F24)*0.368,0),"") -> 0 | N24: =IFERROR(ROUND($F24+($G24-$F24)*0.214,0),"") -> 0 | V24: {=IFERROR(_xlfn.IFS(O24="F2",U24/K24,O24="F23",U24/L24,O24="F234",U24/M24,O24="F3",U24/L24,O24="F34",U24/M24,O24="F234손절",U24/K24,O24="F2345손절",U24/K24,O24="F34손절",U24/L24,O24="F345손절",U24/L24)-1,"")}
A25: 신성이엔지 | B25: 2600 | C25: =IFERROR($X$1*10000/D25,"") -> 206.18557 | D25: 2425 | E25: =IFERROR(D25/B25-1,"") -> -0.067307692 | F25: 2070 | G25: 3035 | H25: 45104 | I25: +4 | J25: =IFERROR(G25/F25-1,"") -> 0.46618357 | K25: =IFERROR(ROUND($F25+($G25-$F25)*0.632,0),"") -> 2680 | L25: =IFERROR(ROUND($F25+($G25-$F25)*0.5,0),"") -> 2553 | M25: =IFERROR(ROUND($F25+($G25-$F25)*0.368,0),"") -> 2425 | N25: =IFERROR(ROUND($F25+($G25-$F25)*0.214,0),"") -> 2277 | P25: +2 | Q25: +1 | V25: {=IFERROR(_xlfn.IFS(O25="F2",U25/K25,O25="F23",U25/L25,O25="F234",U25/M25,O25="F3",U25/L25,O25="F34",U25/M25,O25="F234손절",U25/K25,O25="F2345손절",U25/K25,O25="F34손절",U25/L25,O25="F345손절",U25/L25)-1,"")}
A26: 케이엔솔 | B26: 11880 | C26: =IFERROR($X$1*10000/D26,"") -> 44.404973 | D26: 11260 | E26: =IFERROR(D26/B26-1,"") -> -0.052188552 | F26: 9990 | G26: 13460 | H26: 45105 | I26: +3 | J26: =IFERROR(G26/F26-1,"") -> 0.34734735 | K26: =IFERROR(ROUND($F26+($G26-$F26)*0.632,0),"") -> 12183 | L26: =IFERROR(ROUND($F26+($G26-$F26)*0.5,0),"") -> 11725 | M26: =IFERROR(ROUND($F26+($G26-$F26)*0.368,0),"") -> 11267 | N26: =IFERROR(ROUND($F26+($G26-$F26)*0.214,0),"") -> 10733 | P26: +2 | Q26: +1 | V26: {=IFERROR(_xlfn.IFS(O26="F2",U26/K26,O26="F23",U26/L26,O26="F234",U26/M26,O26="F3",U26/L26,O26="F34",U26/M26,O26="F234손절",U26/K26,O26="F2345손절",U26/K26,O26="F34손절",U26/L26,O26="F345손절",U26/L26)-1,"")}
C27: =IFERROR($X$1*10000/D27,"") | E27: =IFERROR(D27/B27-1,"") | J27: =IFERROR(G27/F27-1,"") | K27: =COUNTIFS('F series'!T36:T64,#REF!, 'F series'!O36:O64,#REF!) -> 0 | L27: =IFERROR(ROUND($F27+($G27-$F27)*0.5,0),"") -> 0 | M27: =IFERROR(ROUND($F27+($G27-$F27)*0.368,0),"") -> 0 | N27: =IFERROR(ROUND($F27+($G27-$F27)*0.214,0),"") -> 0 | V27: {=IFERROR(_xlfn.IFS(O27="F2",U27/K27,O27="F23",U27/L27,O27="F234",U27/M27,O27="F3",U27/L27,O27="F34",U27/M27,O27="F234손절",U27/K27,O27="F2345손절",U27/K27,O27="F34손절",U27/L27,O27="F345손절",U27/L27)-1,"")}
A28: 풍국주정 | B28: 15470 | C28: =IFERROR($X$1*10000/D28,"") | E28: =IFERROR(D28/B28-1,"") -> -1 | J28: =IFERROR(G28/F28-1,"") | K28: =IFERROR(ROUND($F28+($G28-$F28)*0.632,0),"") -> 0 | L28: =IFERROR(ROUND($F28+($G28-$F28)*0.5,0),"") -> 0 | M28: =IFERROR(ROUND($F28+($G28-$F28)*0.368,0),"") -> 0 | N28: =IFERROR(ROUND($F28+($G28-$F28)*0.214,0),"") -> 0 | V28: {=IFERROR(_xlfn.IFS(O28="F2",U28/K28,O28="F23",U28/L28,O28="F234",U28/M28,O28="F3",U28/L28,O28="F34",U28/M28,O28="F234손절",U28/K28,O28="F2345손절",U28/K28,O28="F34손절",U28/L28,O28="F345손절",U28/L28)-1,"")}
A29: 한일화학 | B29: 27500 | C29: =IFERROR($X$1*10000/D29,"") -> 19.53125 | D29: 25600 | E29: =IFERROR(D29/B29-1,"") -> -0.069090909 | F29: 20350 | G29: 30900 | H29: 45112 | I29: +2 | J29: =IFERROR(G29/F29-1,"") -> 0.51842752 | K29: =IFERROR(ROUND($F29+($G29-$F29)*0.632,0),"") -> 27018 | L29: =IFERROR(ROUND($F29+($G29-$F29)*0.5,0),"") -> 25625 | M29: =IFERROR(ROUND($F29+($G29-$F29)*0.368,0),"") -> 24232 | N29: =IFERROR(ROUND($F29+($G29-$F29)*0.214,0),"") -> 22608 | P29: +0 | V29: {=IFERROR(_xlfn.IFS(O29="F2",U29/K29,O29="F23",U29/L29,O29="F234",U29/M29,O29="F3",U29/L29,O29="F34",U29/M29,O29="F234손절",U29/K29,O29="F2345손절",U29/K29,O29="F34손절",U29/L29,O29="F345손절",U29/L29)-1,"")}
A30: STX | B30: 13240 | C30: =IFERROR($X$1*10000/D30,"") | E30: =IFERROR(D30/B30-1,"") -> -1 | F30: 8790 | G30: 13890 | H30: 45106 | I30: +5 | J30: =IFERROR(G30/F30-1,"") -> 0.58020478 | K30: =IFERROR(ROUND($F30+($G30-$F30)*0.632,0),"") -> 12013 | L30: =IFERROR(ROUND($F30+($G30-$F30)*0.5,0),"") -> 11340 | M30: =IFERROR(ROUND($F30+($G30-$F30)*0.368,0),"") -> 10667 | N30: =IFERROR(ROUND($F30+($G30-$F30)*0.214,0),"") -> 9881 | V30: {=IFERROR(_xlfn.IFS(O30="F2",U30/K30,O30="F23",U30/L30,O30="F234",U30/M30,O30="F3",U30/L30,O30="F34",U30/M30,O30="F234손절",U30/K30,O30="F2345손절",U30/K30,O30="F34손절",U30/L30,O30="F345손절",U30/L30)-1,"")}
A31: RF머트리얼즈 | B31: 13640 | C31: =IFERROR($X$1*10000/D31,"") | E31: =IFERROR(D31/B31-1,"") -> -1 | J31: =IFERROR(G31/F31-1,"") | K31: =IFERROR(ROUND($F31+($G31-$F31)*0.632,0),"") -> 0 | L31: =IFERROR(ROUND($F31+($G31-$F31)*0.5,0),"") -> 0 | M31: =IFERROR(ROUND($F31+($G31-$F31)*0.368,0),"") -> 0 | N31: =IFERROR(ROUND($F31+($G31-$F31)*0.214,0),"") -> 0 | V31: {=IFERROR(_xlfn.IFS(O31="F2",U31/K31,O31="F23",U31/L31,O31="F234",U31/M31,O31="F3",U31/L31,O31="F34",U31/M31,O31="F234손절",U31/K31,O31="F2345손절",U31/K31,O31="F34손절",U31/L31,O31="F345손절",U31/L31)-1,"")}
A32: 동국알앤에스 | B32: 5200 | C32: =IFERROR($X$1*10000/D32,"") -> 101.62602 | D32: 4920 | E32: =IFERROR(D32/B32-1,"") -> -0.053846154 | F32: 4090 | G32: 6350 | H32: 45107 | I32: +5 | J32: =IFERROR(G32/F32-1,"") -> 0.55256724 | K32: =IFERROR(ROUND($F32+($G32-$F32)*0.632,0),"") -> 5518 | L32: =IFERROR(ROUND($F32+($G32-$F32)*0.5,0),"") -> 5220 | M32: =IFERROR(ROUND($F32+($G32-$F32)*0.368,0),"") -> 4922 | N32: =IFERROR(ROUND($F32+($G32-$F32)*0.214,0),"") -> 4574 | P32: +0 | Q32: +0 | V32: {=IFERROR(_xlfn.IFS(O32="F2",U32/K32,O32="F23",U32/L32,O32="F234",U32/M32,O32="F3",U32/L32,O32="F34",U32/M32,O32="F234손절",U32/K32,O32="F2345손절",U32/K32,O32="F34손절",U32/L32,O32="F345손절",U32/L32)-1,"")}
A33: 성안 | B33: 2220 | C33: =IFERROR($X$1*10000/D33,"") | E33: =IFERROR(D33/B33-1,"") -> -1 | J33: =IFERROR(G33/F33-1,"") | K33: =IFERROR(ROUND($F33+($G33-$F33)*0.632,0),"") -> 0 | L33: =IFERROR(ROUND($F33+($G33-$F33)*0.5,0),"") -> 0 | M33: =IFERROR(ROUND($F33+($G33-$F33)*0.368,0),"") -> 0 | N33: =IFERROR(ROUND($F33+($G33-$F33)*0.214,0),"") -> 0 | V33: {=IFERROR(_xlfn.IFS(O33="F2",U33/K33,O33="F23",U33/L33,O33="F234",U33/M33,O33="F3",U33/L33,O33="F34",U33/M33,O33="F234손절",U33/K33,O33="F2345손절",U33/K33,O33="F34손절",U33/L33,O33="F345손절",U33/L33)-1,"")}
C34: =IFERROR($X$1*10000/D34,"") | E34: =IFERROR(D34/B34-1,"") | J34: =IFERROR(G34/F34-1,"") | K34: =COUNTIFS('F series'!T43:T71,#REF!, 'F series'!O43:O71,#REF!) -> 0 | L34: =IFERROR(ROUND($F34+($G34-$F34)*0.5,0),"") -> 0 | M34: =IFERROR(ROUND($F34+($G34-$F34)*0.368,0),"") -> 0 | N34: =IFERROR(ROUND($F34+($G34-$F34)*0.214,0),"") -> 0 | V34: {=IFERROR(_xlfn.IFS(O34="F2",U34/K34,O34="F23",U34/L34,O34="F234",U34/M34,O34="F3",U34/L34,O34="F34",U34/M34,O34="F234손절",U34/K34,O34="F2345손절",U34/K34,O34="F34손절",U34/L34,O34="F345손절",U34/L34)-1,"")}
A35: 금양 | B35: 83000 | C35: =IFERROR($X$1*10000/D35,"") -> 6.5616798 | D35: 76200 | E35: =IFERROR(D35/B35-1,"") -> -0.081927711 | F35: 56500 | G35: 87800 | H35: 45111 | I35: +3 | J35: =IFERROR(G35/F35-1,"") -> 0.5539823 | K35: =IFERROR(ROUND($F35+($G35-$F35)*0.632,0),"") -> 76282 | L35: =IFERROR(ROUND($F35+($G35-$F35)*0.5,0),"") -> 72150 | M35: =IFERROR(ROUND($F35+($G35-$F35)*0.368,0),"") -> 68018 | N35: =IFERROR(ROUND($F35+($G35-$F35)*0.214,0),"") -> 63198 | V35: {=IFERROR(_xlfn.IFS(O35="F2",U35/K35,O35="F23",U35/L35,O35="F234",U35/M35,O35="F3",U35/L35,O35="F34",U35/M35,O35="F234손절",U35/K35,O35="F2345손절",U35/K35,O35="F34손절",U35/L35,O35="F345손절",U35/L35)-1,"")}
A36: 롯데에너지머티리얼즈 | B36: 54700 | C36: =IFERROR($X$1*10000/D36,"") | E36: =IFERROR(D36/B36-1,"") -> -1 | J36: =IFERROR(G36/F36-1,"") | K36: =IFERROR(ROUND($F36+($G36-$F36)*0.632,0),"") -> 0 | L36: =IFERROR(ROUND($F36+($G36-$F36)*0.5,0),"") -> 0 | M36: =IFERROR(ROUND($F36+($G36-$F36)*0.368,0),"") -> 0 | N36: =IFERROR(ROUND($F36+($G36-$F36)*0.214,0),"") -> 0 | V36: {=IFERROR(_xlfn.IFS(O36="F2",U36/K36,O36="F23",U36/L36,O36="F234",U36/M36,O36="F3",U36/L36,O36="F34",U36/M36,O36="F234손절",U36/K36,O36="F2345손절",U36/K36,O36="F34손절",U36/L36,O36="F345손절",U36/L36)-1,"")}
A37: 코스모화학 | B37: 56400 | C37: =IFERROR($X$1*10000/D37,"") | E37: =IFERROR(D37/B37-1,"") -> -1 | J37: =IFERROR(G37/F37-1,"") | K37: =IFERROR(ROUND($F37+($G37-$F37)*0.632,0),"") -> 0 | L37: =IFERROR(ROUND($F37+($G37-$F37)*0.5,0),"") -> 0 | M37: =IFERROR(ROUND($F37+($G37-$F37)*0.368,0),"") -> 0 | N37: =IFERROR(ROUND($F37+($G37-$F37)*0.214,0),"") -> 0 | V37: {=IFERROR(_xlfn.IFS(O37="F2",U37/K37,O37="F23",U37/L37,O37="F234",U37/M37,O37="F3",U37/L37,O37="F34",U37/M37,O37="F234손절",U37/K37,O37="F2345손절",U37/K37,O37="F34손절",U37/L37,O37="F345손절",U37/L37)-1,"")}
A38: 에코프로 | B38: 980000 | C38: =IFERROR($X$1*10000/D38,"") | E38: =IFERROR(D38/B38-1,"") -> -1 | J38: =IFERROR(G38/F38-1,"") | K38: =IFERROR(ROUND($F38+($G38-$F38)*0.632,0),"") -> 0 | L38: =IFERROR(ROUND($F38+($G38-$F38)*0.5,0),"") -> 0 | M38: =IFERROR(ROUND($F38+($G38-$F38)*0.368,0),"") -> 0 | N38: =IFERROR(ROUND($F38+($G38-$F38)*0.214,0),"") -> 0 | V38: {=IFERROR(_xlfn.IFS(O38="F2",U38/K38,O38="F23",U38/L38,O38="F234",U38/M38,O38="F3",U38/L38,O38="F34",U38/M38,O38="F234손절",U38/K38,O38="F2345손절",U38/K38,O38="F34손절",U38/L38,O38="F345손절",U38/L38)-1,"")}
A39: 테라사이언스 | B39: 6230 | C39: =IFERROR($X$1*10000/D39,"") | E39: =IFERROR(D39/B39-1,"") -> -1 | J39: =IFERROR(G39/F39-1,"") | K39: =IFERROR(ROUND($F39+($G39-$F39)*0.632,0),"") -> 0 | L39: =IFERROR(ROUND($F39+($G39-$F39)*0.5,0),"") -> 0 | M39: =IFERROR(ROUND($F39+($G39-$F39)*0.368,0),"") -> 0 | N39: =IFERROR(ROUND($F39+($G39-$F39)*0.214,0),"") -> 0 | V39: {=IFERROR(_xlfn.IFS(O39="F2",U39/K39,O39="F23",U39/L39,O39="F234",U39/M39,O39="F3",U39/L39,O39="F34",U39/M39,O39="F234손절",U39/K39,O39="F2345손절",U39/K39,O39="F34손절",U39/L39,O39="F345손절",U39/L39)-1,"")}
A40: 하나기술 | B40: 97900 | C40: =IFERROR($X$1*10000/D40,"") -> 5.5865922 | D40: 89500 | E40: =IFERROR(D40/B40-1,"") -> -0.085801839 | F40: 74400 | G40: 104700 | H40: 45103 | I40: +8 | J40: =IFERROR(G40/F40-1,"") -> 0.40725806 | K40: =IFERROR(ROUND($F40+($G40-$F40)*0.632,0),"") -> 93550 | L40: =IFERROR(ROUND($F40+($G40-$F40)*0.5,0),"") -> 89550 | M40: =IFERROR(ROUND($F40+($G40-$F40)*0.368,0),"") -> 85550 | N40: =IFERROR(ROUND($F40+($G40-$F40)*0.214,0),"") -> 80884 | V40: {=IFERROR(_xlfn.IFS(O40="F2",U40/K40,O40="F23",U40/L40,O40="F234",U40/M40,O40="F3",U40/L40,O40="F34",U40/M40,O40="F234손절",U40/K40,O40="F2345손절",U40/K40,O40="F34손절",U40/L40,O40="F345손절",U40/L40)-1,"")}
...

Sheet R series
A1: UL date | B1: Corp. | C1: R0 | D1: R1 | E1: R2 | F1: R3 | G1: R Series | H1: buy1 | I1: buy2 | J1: sell | K1: sell date | L1: sell price | M1: rbn rate | O1: sell
A2: 45103 | B2: 동운아나텍 | C2: 15990 | D2: =F2+(C2-F2)*2/3 -> 14760 | E2: =F2+(C2-F2)*1/3 -> 13530 | F2: 12300 | G2: time over | M2: =IFERROR(IF(G2="R1성공", L2/D2, IF(G2="R1탈출", L2/D2, IF(G2="R12탈출", L2/AVERAGE(D2:E2), IF(G2="R123손절", L2/(D2+E2)/2, ""))))-1,"")
A3: 45104 | B3: 카페24 | C3: 15390 | D3: =F3+(C3-F3)*2/3 -> 14206.667 | E3: =F3+(C3-F3)*1/3 -> 13023.333 | F3: 11840 | G3: R1성공 | H3: +3 | J3: +2 | K3: 45111 | L3: 15800 | M3: =IFERROR(IF(G3="R1성공", L3/D3, IF(G3="R1탈출", L3/D3, IF(G3="R12탈출", L3/AVERAGE(D3:E3), IF(G3="R123손절", L3/(D3+E3)/2, ""))))-1,"") -> 0.11215392
A4: 45104 | B4: 에이디엠코리아 | C4: 3015 | D4: =F4+(C4-F4)*2/3 -> 2783.3333 | E4: =F4+(C4-F4)*1/3 -> 2551.6667 | F4: 2320 | M4: =IFERROR(IF(G4="R1성공", L4/D4, IF(G4="R1탈출", L4/D4, IF(G4="R12탈출", L4/AVERAGE(D4:E4), IF(G4="R123손절", L4/(D4+E4)/2, ""))))-1,"")
A5: 45106 | B5: 파이버프로 | C5: 5100 | D5: =F5+(C5-F5)*2/3 -> 4708.3333 | E5: =F5+(C5-F5)*1/3 -> 4316.6667 | F5: 3925 | H5: +4 | M5: =IFERROR(IF(G5="R1성공", L5/D5, IF(G5="R1탈출", L5/D5, IF(G5="R12탈출", L5/AVERAGE(D5:E5), IF(G5="R123손절", L5/(D5+E5)/2, ""))))-1,"")
A6: 45100 | B6: SG | C6: 1512 | D6: =F6+(C6-F6)*2/3 -> 1663 | E6: =F6+(C6-F6)*1/3 -> 1814 | F6: 1965 | G6: R1탈출 | H6: +4 | J6: +2 | K6: 45110 | L6: 1777 | M6: =IFERROR(IF(G6="R1성공", L6/D6, IF(G6="R1탈출", L6/D6, IF(G6="R12탈출", L6/AVERAGE(D6:E6), IF(G6="R123손절", L6/(D6+E6)/2, ""))))-1,"") -> 0.068550812
A7: 45111 | B7: 알멕 | C7: 137200 | D7: =F7+(C7-F7)*2/3 -> 91466.667 | E7: =F7+(C7-F7)*1/3 -> 45733.333 | M7: =IFERROR(IF(G7="R1성공", L7/D7, IF(G7="R1탈출", L7/D7, IF(G7="R12탈출", L7/AVERAGE(D7:E7), IF(G7="R123손절", L7/(D7+E7)/2, ""))))-1,"")
A8: 45111 | B8: 대원강업 | C8: 5850 | D8: =F8+(C8-F8)*2/3 -> 5400 | E8: =F8+(C8-F8)*1/3 -> 4950 | F8: 4500 | M8: =IFERROR(IF(G8="R1성공", L8/D8, IF(G8="R1탈출", L8/D8, IF(G8="R12탈출", L8/AVERAGE(D8:E8), IF(G8="R123손절", L8/(D8+E8)/2, ""))))-1,"")
A9: 45112 | B9: 포커스에이치엔에스 | D9: =F9+(C9-F9)*2/3 -> 0 | E9: =F9+(C9-F9)*1/3 -> 0 | G9: 약한상 | M9: =IFERROR(IF(G9="R1성공", L9/D9, IF(G9="R1탈출", L9/D9, IF(G9="R12탈출", L9/AVERAGE(D9:E9), IF(G9="R123손절", L9/(D9+E9)/2, ""))))-1,"")
A10: 45112 | B10: 한일화학 | C10: 26700 | D10: =F10+(C10-F10)*2/3 -> 24650 | E10: =F10+(C10-F10)*1/3 -> 22600 | F10: 20550 | G10: R1성공 | H10: +2 | J10: +0 | K10: 45114 | L10: 30500 | M10: =IFERROR(IF(G10="R1성공", L10/D10, IF(G10="R1탈출", L10/D10, IF(G10="R12탈출", L10/AVERAGE(D10:E10), IF(G10="R123손절", L10/(D10+E10)/2, ""))))-1,"") -> 0.23732252
A11: 45114 | B11: 다산네트웍스 | C11: 6890 | D11: =F11+(C11-F11)*2/3 -> 6360 | E11: =F11+(C11-F11)*1/3 -> 5830 | F11: 5300 | M11: =IFERROR(IF(G11="R1성공", L11/D11, IF(G11="R1탈출", L11/D11, IF(G11="R12탈출", L11/AVERAGE(D11:E11), IF(G11="R123손절", L11/(D11+E11)/2, ""))))-1,"")
D12: =F12+(C12-F12)*2/3 -> 0 | E12: =F12+(C12-F12)*1/3 -> 0 | M12: =IFERROR(IF(G12="R1성공", L12/D12, IF(G12="R1탈출", L12/D12, IF(G12="R12탈출", L12/AVERAGE(D12:E12), IF(G12="R123손절", L12/(D12+E12)/2, ""))))-1,"")
D13: =F13+(C13-F13)*2/3 -> 0 | E13: =F13+(C13-F13)*1/3 -> 0 | M13: =IFERROR(IF(G13="R1성공", L13/D13, IF(G13="R1탈출", L13/D13, IF(G13="R12탈출", L13/AVERAGE(D13:E13), IF(G13="R123손절", L13/(D13+E13)/2, ""))))-1,"")
D14: =F14+(C14-F14)*2/3 -> 0 | E14: =F14+(C14-F14)*1/3 -> 0 | M14: =IFERROR(IF(G14="R1성공", L14/D14, IF(G14="R1탈출", L14/D14, IF(G14="R12탈출", L14/AVERAGE(D14:E14), IF(G14="R123손절", L14/(D14+E14)/2, ""))))-1,"")
D15: =F15+(C15-F15)*2/3 -> 0 | E15: =F15+(C15-F15)*1/3 -> 0 | M15: =IFERROR(IF(G15="R1성공", L15/D15, IF(G15="R1탈출", L15/D15, IF(G15="R12탈출", L15/AVERAGE(D15:E15), IF(G15="R123손절", L15/(D15+E15)/2, ""))))-1,"")
D16: =F16+(C16-F16)*2/3 -> 0 | E16: =F16+(C16-F16)*1/3 -> 0 | M16: =IFERROR(IF(G16="R1성공", L16/D16, IF(G16="R1탈출", L16/D16, IF(G16="R12탈출", L16/AVERAGE(D16:E16), IF(G16="R123손절", L16/(D16+E16)/2, ""))))-1,"")
D17: =F17+(C17-F17)*2/3 -> 0 | E17: =F17+(C17-F17)*1/3 -> 0 | M17: =IFERROR(IF(G17="R1성공", L17/D17, IF(G17="R1탈출", L17/D17, IF(G17="R12탈출", L17/AVERAGE(D17:E17), IF(G17="R123손절", L17/(D17+E17)/2, ""))))-1,"")
D18: =F18+(C18-F18)*2/3 -> 0 | E18: =F18+(C18-F18)*1/3 -> 0 | M18: =IFERROR(IF(G18="R1성공", L18/D18, IF(G18="R1탈출", L18/D18, IF(G18="R12탈출", L18/AVERAGE(D18:E18), IF(G18="R123손절", L18/(D18+E18)/2, ""))))-1,"")
D19: =F19+(C19-F19)*2/3 -> 0 | E19: =F19+(C19-F19)*1/3 -> 0 | M19: =IFERROR(IF(G19="R1성공", L19/D19, IF(G19="R1탈출", L19/D19, IF(G19="R12탈출", L19/AVERAGE(D19:E19), IF(G19="R123손절", L19/(D19+E19)/2, ""))))-1,"")
D20: =F20+(C20-F20)*2/3 -> 0 | E20: =F20+(C20-F20)*1/3 -> 0 | M20: =IFERROR(IF(G20="R1성공", L20/D20, IF(G20="R1탈출", L20/D20, IF(G20="R12탈출", L20/AVERAGE(D20:E20), IF(G20="R123손절", L20/(D20+E20)/2, ""))))-1,"")
D21: =F21+(C21-F21)*2/3 -> 0 | E21: =F21+(C21-F21)*1/3 -> 0 | M21: =IFERROR(IF(G21="R1성공", L21/D21, IF(G21="R1탈출", L21/D21, IF(G21="R12탈출", L21/AVERAGE(D21:E21), IF(G21="R123손절", L21/(D21+E21)/2, ""))))-1,"")
D22: =F22+(C22-F22)*2/3 -> 0 | E22: =F22+(C22-F22)*1/3 -> 0 | M22: =IFERROR(IF(G22="R1성공", L22/D22, IF(G22="R1탈출", L22/D22, IF(G22="R12탈출", L22/AVERAGE(D22:E22), IF(G22="R123손절", L22/(D22+E22)/2, ""))))-1,"")
D23: =F23+(C23-F23)*2/3 -> 0 | E23: =F23+(C23-F23)*1/3 -> 0 | M23: =IFERROR(IF(G23="R1성공", L23/D23, IF(G23="R1탈출", L23/D23, IF(G23="R12탈출", L23/AVERAGE(D23:E23), IF(G23="R123손절", L23/(D23+E23)/2, ""))))-1,"")
... D36: =F36+(C36-F36)*2/3 -> 0 | E36: =F36+(C36-F36)*1/3 -> 0 | M36: =IFERROR(IF(G36="R1성공", L36/D36, IF(G36="R1탈출", L36/D36, IF(G36="R12탈출", L36/AVERAGE(D36:E36), IF(G36="R123손절", L36/(D36+E36)/2, ""))))-1,"")
